<sdf version='1.6'>
  <world name='default'>
    <light name='sun' type='directional'>
      <cast_shadows>1</cast_shadows>
      <pose frame=''>0 0 10 0 -0 0</pose>
      <diffuse>0.8 0.8 0.8 1</diffuse>
      <specular>0.2 0.2 0.2 1</specular>
      <attenuation>
        <range>1000</range>
        <constant>0.9</constant>
        <linear>0.01</linear>
        <quadratic>0.001</quadratic>
      </attenuation>
      <direction>-0.5 0.1 -0.9</direction>
    </light>
    <model name='ground_plane'>
      <static>1</static>
      <link name='link'>
        <collision name='collision'>
          <geometry>
            <plane>
              <normal>0 0 1</normal>
              <size>100 100</size>
            </plane>
          </geometry>
          <surface>
            <contact>
              <collide_bitmask>65535</collide_bitmask>
              <ode/>
            </contact>
            <friction>
              <ode>
                <mu>100</mu>
                <mu2>50</mu2>
              </ode>
              <torsional>
                <ode/>
              </torsional>
            </friction>
            <bounce/>
          </surface>
          <max_contacts>10</max_contacts>
        </collision>
        <visual name='visual'>
          <cast_shadows>0</cast_shadows>
          <geometry>
            <plane>
              <normal>0 0 1</normal>
              <size>100 100</size>
            </plane>
          </geometry>
          <material>
            <script>
              <uri>file://media/materials/scripts/gazebo.material</uri>
              <name>Gazebo/Grey</name>
            </script>
          </material>
        </visual>
        <self_collide>0</self_collide>
        <enable_wind>0</enable_wind>
        <kinematic>0</kinematic>
      </link>
    </model>
    <gravity>0 0 -9.8</gravity>
    <magnetic_field>6e-06 2.3e-05 -4.2e-05</magnetic_field>
    <atmosphere type='adiabatic'/>
    <physics name='default_physics' default='0' type='ode'>
      <max_step_size>0.001</max_step_size>
      <real_time_factor>1</real_time_factor>
      <real_time_update_rate>1000</real_time_update_rate>
    </physics>
    <scene>
      <ambient>0.4 0.4 0.4 1</ambient>
      <background>0.7 0.7 0.7 1</background>
      <shadows>1</shadows>
    </scene>
    <audio>
      <device>default</device>
    </audio>
    <wind/>
    <spherical_coordinates>
      <surface_model>EARTH_WGS84</surface_model>
      <latitude_deg>0</latitude_deg>
      <longitude_deg>0</longitude_deg>
      <elevation>0</elevation>
      <heading_deg>0</heading_deg>
    </spherical_coordinates>
    <state world_name='default'>
      <sim_time>1594 329000000</sim_time>
      <real_time>652 84204859</real_time>
      <wall_time>1606926341 833167320</wall_time>
      <iterations>573275</iterations>
      <model name='camera'>
        <pose frame=''>0 -0 -0 0 -0 0</pose>
        <scale>1 1 1</scale>
        <link name='camera_link'>
          <pose frame=''>0 0 1 3.14159 1.57079 3.14159</pose>
          <velocity>0 0 -0 0 -0 0</velocity>
          <acceleration>0 0 -0 0 -0 0</acceleration>
          <wrench>0 0 -0 0 -0 0</wrench>
        </link>
      </model>
      <model name='ground_plane'>
        <pose frame=''>0 0 0 0 -0 0</pose>
        <scale>1 1 1</scale>
        <link name='link'>
          <pose frame=''>0 0 0 0 -0 0</pose>
          <velocity>0 0 0 0 -0 0</velocity>
          <acceleration>0 0 0 0 -0 0</acceleration>
          <wrench>0 0 0 0 -0 0</wrench>
        </link>
      </model>
      <model name='phantomXPincher'>
        <pose frame=''>0 0.25 0 0 -0 0</pose>
        <scale>1 1 1</scale>
        <link name='base_link'>
          <pose frame=''>0 0.25 0 0 -0 0</pose>
          <velocity>0 0 -0 0 -0 0</velocity>
          <acceleration>-1e-06 -3.3e-05 0 1.8e-05 4e-06 0</acceleration>
          <wrench>-0 -1.9e-05 0 0 -0 0</wrench>
        </link>
        <link name='link1'>
          <pose frame=''>0 0.25 0.053333 0 -0 0</pose>
          <velocity>0 0 -0 0 -0 0</velocity>
          <acceleration>-2e-06 -0.000161 1e-06 0.000443 -2.5e-05 -2e-06</acceleration>
          <wrench>-0 -1.1e-05 0 0 -0 0</wrench>
        </link>
        <link name='link2'>
          <pose frame=''>-0 0.25 0.125333 -1.5713 -1.57079 -3.14109</pose>
          <velocity>-0 -0 0 0 -0 0</velocity>
          <acceleration>1.7e-05 0.000577 -2e-06 -0.001044 0.00095 2e-06</acceleration>
          <wrench>2e-06 6.5e-05 -0 0 -0 0</wrench>
        </link>
        <link name='link3'>
          <pose frame=''>-0 0.25 0.232333 -1.57137 -1.57079 -3.14101</pose>
          <velocity>-0 -0 0 0 -0 0</velocity>
          <acceleration>3.3e-05 0.001169 -3e-06 -0.001198 0.001734 2e-06</acceleration>
          <wrench>4e-06 0.000132 -0 0 -0 0</wrench>
        </link>
        <link name='link4'>
          <pose frame=''>-0 0.25 0.339333 -1.57139 -1.57079 -3.141</pose>
          <velocity>-0 -0 0 0 -0 0</velocity>
          <acceleration>5.1e-05 0.001667 -4e-06 0.823641 1.38568 -1.73203</acceleration>
          <wrench>3e-06 9.5e-05 -0 0 -0 0</wrench>
        </link>
        <link name='link5'>
          <pose frame=''>-0 0.25 0.339333 -1.57156 -1.57079 -3.14083</pose>
          <velocity>-0 -1e-06 0 0 -0 0</velocity>
          <acceleration>8.6e-05 0.002325 3.7e-05 -0.003694 -0.002271 0.002221</acceleration>
          <wrench>2e-06 4.2e-05 1e-06 0 -0 0</wrench>
        </link>
        <link name='link6'>
          <pose frame=''>-0 0.25 0.339333 -1.57151 -1.57079 -3.14087</pose>
          <velocity>-0 -1e-06 0 0 -0 0</velocity>
          <acceleration>7.2e-05 0.002169 -4.9e-05 0.975822 -0.729917 2.90688</acceleration>
          <wrench>4e-06 0.000124 -3e-06 0 -0 0</wrench>
        </link>
      </model>
      <model name='phantomXPincher2'>
        <pose frame=''>0 -0.25 0 0 -0 0</pose>
        <scale>1 1 1</scale>
        <link name='base_link'>
          <pose frame=''>0 -0.25 0 0 -0 0</pose>
          <velocity>0 0 -0 0 -0 0</velocity>
          <acceleration>2e-06 8.5e-05 -0 -5.1e-05 -1e-05 0</acceleration>
          <wrench>1e-06 4.8e-05 -0 0 -0 0</wrench>
        </link>
        <link name='link1'>
          <pose frame=''>0 -0.25 0.053333 0 -0 0</pose>
          <velocity>0 0 -0 -1e-06 0 0</velocity>
          <acceleration>5e-06 0.000403 -2e-06 -0.001205 6e-05 1.1e-05</acceleration>
          <wrench>0 2.8e-05 -0 0 -0 0</wrench>
        </link>
        <link name='link2'>
          <pose frame=''>-0 -0.25 0.125333 -1.57131 -1.57079 -3.14108</pose>
          <velocity>-0 -1e-06 0 1e-06 -0 0</velocity>
          <acceleration>-4.3e-05 -0.001478 5e-06 0.00284 -0.003111 -6e-06</acceleration>
          <wrench>-5e-06 -0.000167 1e-06 0 -0 0</wrench>
        </link>
        <link name='link3'>
          <pose frame=''>-0 -0.25 0.232333 -1.57138 -1.57079 -3.141</pose>
          <velocity>-0 -1e-06 0 1e-06 -0 0</velocity>
          <acceleration>-8.7e-05 -0.00301 8e-06 0.003259 -0.005398 -6e-06</acceleration>
          <wrench>-1e-05 -0.00034 1e-06 0 -0 0</wrench>
        </link>
        <link name='link4'>
          <pose frame=''>-0 -0.25 0.339333 -1.5714 -1.57079 -3.14098</pose>
          <velocity>-0 -2e-06 0 2e-06 -0 0</velocity>
          <acceleration>-0.000136 -0.004307 1e-05 0.83684 1.39029 -1.73231</acceleration>
          <wrench>-8e-06 -0.000245 1e-06 0 -0 0</wrench>
        </link>
        <link name='link5'>
          <pose frame=''>-0 -0.25 0.339333 -1.57157 -1.57079 -3.14081</pose>
          <velocity>-0 -3e-06 0 2e-06 -0 0</velocity>
          <acceleration>-0.00023 -0.006276 -9.9e-05 0.010048 0.006151 -0.006035</acceleration>
          <wrench>-4e-06 -0.000113 -2e-06 0 -0 0</wrench>
        </link>
        <link name='link6'>
          <pose frame=''>-0 -0.25 0.339333 -1.57153 -1.57079 -3.14086</pose>
          <velocity>-0 -3e-06 0 2e-06 -0 0</velocity>
          <acceleration>-0.000193 -0.005803 0.000132 0.993207 -0.746329 2.9185</acceleration>
          <wrench>-1.1e-05 -0.000331 8e-06 0 -0 0</wrench>
        </link>
      </model>
      <model name='unit_box'>
        <pose frame=''>0.283533 0.017471 0.005889 3e-06 1e-05 4.3e-05</pose>
        <scale>1.12851 1 0.073614</scale>
        <link name='link'>
          <pose frame=''>0.283533 0.017471 0.005889 3e-06 1e-05 4.3e-05</pose>
          <velocity>0 0 0 0 -0 0</velocity>
          <acceleration>0.058765 -0.016577 -1.5e-05 -0.326892 -0.553545 -3.14158</acceleration>
          <wrench>0.058765 -0.016577 -1.5e-05 0 -0 0</wrench>
        </link>
      </model>
      <model name='unit_box_0'>
        <pose frame=''>-0.210055 -0.251279 0.04 0 -0 2.4e-05</pose>
        <scale>0.5 0.6 0.4</scale>
        <link name='link'>
          <pose frame=''>-0.210055 -0.251279 0.04 0 -0 2.4e-05</pose>
          <velocity>0 0 0 0 -0 0</velocity>
          <acceleration>-3e-06 -2e-06 1e-05 4.1e-05 -7.8e-05 0</acceleration>
          <wrench>-3e-06 -2e-06 1e-05 0 -0 0</wrench>
        </link>
      </model>
      <model name='unit_box_1'>
        <pose frame=''>-0.209134 0.230725 0.02 0 0 -1.7e-05</pose>
        <scale>0.5 0.6 0.2</scale>
        <link name='link'>
          <pose frame=''>-0.209134 0.230725 0.02 0 0 -1.7e-05</pose>
          <velocity>0 0 0 0 -0 0</velocity>
          <acceleration>1e-06 1e-06 -1e-05 -2.7e-05 5.7e-05 0</acceleration>
          <wrench>1e-06 1e-06 -1e-05 0 -0 0</wrench>
        </link>
      </model>
      <model name='unit_box_2'>
        <pose frame=''>0.287137 0.002798 0.022719 1.8e-05 1e-05 0.000174</pose>
        <scale>0.288746 0.068747 0.021881</scale>
        <link name='link'>
          <pose frame=''>0.287137 0.002798 0.022719 1.8e-05 1e-05 0.000174</pose>
          <velocity>0 0 0 0 -0 0</velocity>
          <acceleration>0.015915 1.1e-05 3.97958 0.301321 -0.089421 -3.127</acceleration>
          <wrench>0.015915 1.1e-05 3.97958 0 -0 0</wrench>
        </link>
      </model>
      <light name='sun'>
        <pose frame=''>0 0 10 0 -0 0</pose>
      </light>
    </state>
    <model name='unit_box'>
      <pose frame=''>0.7 0 0.2 0 -0 0</pose>
      <link name='link'>
        <inertial>
          <mass>1</mass>
          <inertia>
            <ixx>0.166667</ixx>
            <ixy>0</ixy>
            <ixz>0</ixz>
            <iyy>0.166667</iyy>
            <iyz>0</iyz>
            <izz>0.166667</izz>
          </inertia>
        </inertial>
        <collision name='collision'>
          <geometry>
            <box>
              <size>0.25 1 0.159996</size>
            </box>
          </geometry>
          <max_contacts>10</max_contacts>
          <surface>
            <contact>
              <ode/>
            </contact>
            <bounce/>
            <friction>
              <torsional>
                <ode/>
              </torsional>
              <ode/>
            </friction>
          </surface>
        </collision>
        <visual name='visual'>
          <geometry>
            <box>
              <size>0.25 1 0.159996</size>
            </box>
          </geometry>
          <material>
            <script>
              <name>Gazebo/SkyBlue</name>
              <uri>file://media/materials/scripts/gazebo.material</uri>
            </script>
          </material>
        </visual>
        <self_collide>0</self_collide>
        <enable_wind>0</enable_wind>
        <kinematic>0</kinematic>
      </link>
    </model>
    <model name='unit_box_0'>
      <pose frame=''>-0.7 -0.3 0 0 -0 0</pose>
      <link name='link'>
        <inertial>
          <mass>1</mass>
          <inertia>
            <ixx>0.166667</ixx>
            <ixy>0</ixy>
            <ixz>0</ixz>
            <iyy>0.166667</iyy>
            <iyz>0</iyz>
            <izz>0.166667</izz>
          </inertia>
        </inertial>
        <collision name='collision'>
          <geometry>
            <box>
              <size>0.5 0.8 0.2</size>
            </box>
          </geometry>
          <max_contacts>10</max_contacts>
          <surface>
            <contact>
              <ode/>
            </contact>
            <bounce/>
            <friction>
              <torsional>
                <ode/>
              </torsional>
              <ode/>
            </friction>
          </surface>
        </collision>
        <visual name='visual'>
          <geometry>
            <box>
              <size>0.5 0.8 0.2</size>
            </box>
          </geometry>
          <material>
            <script>
              <name>Gazebo/DarkYellow</name>
              <uri>file://media/materials/scripts/gazebo.material</uri>
            </script>
          </material>
        </visual>
        <self_collide>0</self_collide>
        <enable_wind>0</enable_wind>
        <kinematic>0</kinematic>
      </link>
    </model>
    <model name='unit_box_1'>
      <pose frame=''>-0.7 0.2 0.1 0 -0 0</pose>
      <link name='link'>
        <inertial>
          <mass>1</mass>
          <inertia>
            <ixx>0.166667</ixx>
            <ixy>0</ixy>
            <ixz>0</ixz>
            <iyy>0.166667</iyy>
            <iyz>0</iyz>
            <izz>0.166667</izz>
          </inertia>
        </inertial>
        <collision name='collision'>
          <geometry>
            <box>
              <size>0.5 0.8 0.2</size>
            </box>
          </geometry>
          <max_contacts>10</max_contacts>
          <surface>
            <contact>
              <ode/>
            </contact>
            <bounce/>
            <friction>
              <torsional>
                <ode/>
              </torsional>
              <ode/>
            </friction>
          </surface>
        </collision>
        <visual name='visual'>
          <geometry>
            <box>
              <size>0.5 0.8 0.2</size>
            </box>
          </geometry>
          <material>
            <script>
              <name>Gazebo/Orange</name>
              <uri>file://media/materials/scripts/gazebo.material</uri>
            </script>
          </material>
        </visual>
        <self_collide>0</self_collide>
        <enable_wind>0</enable_wind>
        <kinematic>0</kinematic>
      </link>
    </model>
    <gui fullscreen='0'>
      <camera name='user_camera'>
        <pose frame=''>1.15891 1.35541 1.00557 0 0.533796 -2.32293</pose>
        <view_controller>orbit</view_controller>
        <projection_type>perspective</projection_type>
      </camera>
    </gui>
    <model name='phantomXPincher'>
      <link name='base_link'>
        <pose frame=''>0 0 0 0 -0 0</pose>
        <inertial>
          <pose frame=''>0 0 0 0 -0 3.14159</pose>
          <mass>0.561</mass>
          <inertia>
            <ixx>158.994</ixx>
            <ixy>-90.0553</ixy>
            <ixz>-15.0968</ixz>
            <iyy>66.0441</iyy>
            <iyz>-24.165</iyz>
            <izz>212.743</izz>
          </inertia>
        </inertial>
        <collision name='base_link_collision'>
          <pose frame=''>0 0 0 0 -0 3.14159</pose>
          <geometry>
            <mesh>
              <scale>1 1 1</scale>
              <uri>/home/gustavo/catkin_ws/src/Robotica-ProyectoIntermedio/Intermedio/meshes/PincherBase.dae</uri>
            </mesh>
          </geometry>
          <max_contacts>10</max_contacts>
          <surface>
            <contact>
              <ode/>
            </contact>
            <bounce/>
            <friction>
              <torsional>
                <ode/>
              </torsional>
              <ode/>
            </friction>
          </surface>
        </collision>
        <visual name='base_link_visual'>
          <pose frame=''>0 0 0 0 -0 3.14159</pose>
          <geometry>
            <mesh>
              <scale>1 1 1</scale>
              <uri>/home/gustavo/catkin_ws/src/Robotica-ProyectoIntermedio/Intermedio/meshes/PincherBase.dae</uri>
            </mesh>
          </geometry>
        </visual>
        <self_collide>0</self_collide>
        <enable_wind>0</enable_wind>
        <kinematic>0</kinematic>
      </link>
      <joint name='fixed' type='fixed'>
        <child>base_link</child>
        <parent>world</parent>
      </joint>
      <link name='link1'>
        <pose frame=''>0 0 0.053333 0 -0 0</pose>
        <inertial>
          <pose frame=''>0 0 0.03 0 -0 0</pose>
          <mass>0.069</mass>
          <inertia>
            <ixx>0.73346</ixx>
            <ixy>0</ixy>
            <ixz>0</ixz>
            <iyy>0.14452</iyy>
            <iyz>0</iyz>
            <izz>0.70391</izz>
          </inertia>
        </inertial>
        <collision name='link1_collision'>
          <pose frame=''>0 0 0.03 0 -0 0</pose>
          <geometry>
            <mesh>
              <scale>1 1 1</scale>
              <uri>/home/gustavo/catkin_ws/src/Robotica-ProyectoIntermedio/Intermedio/meshes/PincherLink1.dae</uri>
            </mesh>
          </geometry>
          <max_contacts>10</max_contacts>
          <surface>
            <contact>
              <ode/>
            </contact>
            <bounce/>
            <friction>
              <torsional>
                <ode/>
              </torsional>
              <ode/>
            </friction>
          </surface>
        </collision>
        <visual name='link1_visual'>
          <pose frame=''>0 0 0.03 0 -0 0</pose>
          <geometry>
            <mesh>
              <scale>1 1 1</scale>
              <uri>/home/gustavo/catkin_ws/src/Robotica-ProyectoIntermedio/Intermedio/meshes/PincherLink1.dae</uri>
            </mesh>
          </geometry>
        </visual>
        <self_collide>0</self_collide>
        <enable_wind>0</enable_wind>
        <kinematic>0</kinematic>
      </link>
      <joint name='cadera' type='revolute'>
        <child>link1</child>
        <parent>base_link</parent>
        <axis>
          <xyz>0 0 1</xyz>
          <limit>
            <lower>-2.61799</lower>
            <upper>2.618</upper>
            <effort>1000</effort>
            <velocity>0.5</velocity>
          </limit>
          <dynamics>
            <spring_reference>0</spring_reference>
            <spring_stiffness>0</spring_stiffness>
          </dynamics>
          <use_parent_model_frame>1</use_parent_model_frame>
        </axis>
      </joint>
      <link name='link2'>
        <pose frame=''>0 0 0.125333 -1.57079 -1.57079 3.14159</pose>
        <inertial>
          <pose frame=''>0 0 0 1.57079 -0 1.57079</pose>
          <mass>0.113</mass>
          <inertia>
            <ixx>7.19462</ixx>
            <ixy>-0.00352</ixy>
            <ixz>0</ixz>
            <iyy>0.27381</iyy>
            <iyz>0</iyz>
            <izz>7.10335</izz>
          </inertia>
        </inertial>
        <collision name='link2_collision'>
          <pose frame=''>0 0 0 1.57079 -0 1.57079</pose>
          <geometry>
            <mesh>
              <scale>1 1 1</scale>
              <uri>/home/gustavo/catkin_ws/src/Robotica-ProyectoIntermedio/Intermedio/meshes/PincherLink2.dae</uri>
            </mesh>
          </geometry>
          <max_contacts>10</max_contacts>
          <surface>
            <contact>
              <ode/>
            </contact>
            <bounce/>
            <friction>
              <torsional>
                <ode/>
              </torsional>
              <ode/>
            </friction>
          </surface>
        </collision>
        <visual name='link2_visual'>
          <pose frame=''>0 0 0 1.57079 -0 1.57079</pose>
          <geometry>
            <mesh>
              <scale>1 1 1</scale>
              <uri>/home/gustavo/catkin_ws/src/Robotica-ProyectoIntermedio/Intermedio/meshes/PincherLink2.dae</uri>
            </mesh>
          </geometry>
        </visual>
        <self_collide>0</self_collide>
        <enable_wind>0</enable_wind>
        <kinematic>0</kinematic>
      </link>
      <joint name='hombro' type='revolute'>
        <child>link2</child>
        <parent>link1</parent>
        <axis>
          <xyz>-1e-06 -1 0</xyz>
          <limit>
            <lower>-2</lower>
            <upper>2.61799</upper>
            <effort>1000</effort>
            <velocity>0.5</velocity>
          </limit>
          <dynamics>
            <spring_reference>0</spring_reference>
            <spring_stiffness>0</spring_stiffness>
          </dynamics>
          <use_parent_model_frame>1</use_parent_model_frame>
        </axis>
      </joint>
      <link name='link3'>
        <pose frame=''>0 -0 0.232333 -1.57079 -1.57079 3.14159</pose>
        <inertial>
          <pose frame=''>0 0 0 1.57079 -0 1.57079</pose>
          <mass>0.113</mass>
          <inertia>
            <ixx>7.19462</ixx>
            <ixy>-0.00352</ixy>
            <ixz>0</ixz>
            <iyy>0.27381</iyy>
            <iyz>0</iyz>
            <izz>7.10335</izz>
          </inertia>
        </inertial>
        <collision name='link3_collision'>
          <pose frame=''>0 0 0 1.57079 -0 1.57079</pose>
          <geometry>
            <mesh>
              <scale>1 1 1</scale>
              <uri>/home/gustavo/catkin_ws/src/Robotica-ProyectoIntermedio/Intermedio/meshes/PincherLink3.dae</uri>
            </mesh>
          </geometry>
          <max_contacts>10</max_contacts>
          <surface>
            <contact>
              <ode/>
            </contact>
            <bounce/>
            <friction>
              <torsional>
                <ode/>
              </torsional>
              <ode/>
            </friction>
          </surface>
        </collision>
        <visual name='link3_visual'>
          <pose frame=''>0 0 0 1.57079 -0 1.57079</pose>
          <geometry>
            <mesh>
              <scale>1 1 1</scale>
              <uri>/home/gustavo/catkin_ws/src/Robotica-ProyectoIntermedio/Intermedio/meshes/PincherLink3.dae</uri>
            </mesh>
          </geometry>
        </visual>
        <self_collide>0</self_collide>
        <enable_wind>0</enable_wind>
        <kinematic>0</kinematic>
      </link>
      <joint name='codo' type='revolute'>
        <child>link3</child>
        <parent>link2</parent>
        <axis>
          <xyz>-1e-06 -1 0</xyz>
          <limit>
            <lower>-2.52</lower>
            <upper>2.52</upper>
            <effort>1000</effort>
            <velocity>0.5</velocity>
          </limit>
          <dynamics>
            <spring_reference>0</spring_reference>
            <spring_stiffness>0</spring_stiffness>
          </dynamics>
          <use_parent_model_frame>1</use_parent_model_frame>
        </axis>
      </joint>
      <link name='link4'>
        <pose frame=''>0 -0 0.339333 -1.57079 -1.57079 3.14159</pose>
        <inertial>
          <pose frame=''>0 0 0 1.57079 -0 1.57079</pose>
          <mass>0.057</mass>
          <inertia>
            <ixx>0.25116</ixx>
            <ixy>0.14167</ixy>
            <ixz>0</ixz>
            <iyy>0.43376</iyy>
            <iyz>0</iyz>
            <izz>0.57362</izz>
          </inertia>
        </inertial>
        <collision name='link4_collision'>
          <pose frame=''>0 0 0 1.57079 -0 1.57079</pose>
          <geometry>
            <mesh>
              <scale>1 1 1</scale>
              <uri>/home/gustavo/catkin_ws/src/Robotica-ProyectoIntermedio/Intermedio/meshes/PincherTool.dae</uri>
            </mesh>
          </geometry>
          <max_contacts>10</max_contacts>
          <surface>
            <contact>
              <ode/>
            </contact>
            <bounce/>
            <friction>
              <torsional>
                <ode/>
              </torsional>
              <ode/>
            </friction>
          </surface>
        </collision>
        <visual name='link4_visual'>
          <pose frame=''>0 0 0 1.57079 -0 1.57079</pose>
          <geometry>
            <mesh>
              <scale>1 1 1</scale>
              <uri>/home/gustavo/catkin_ws/src/Robotica-ProyectoIntermedio/Intermedio/meshes/PincherTool.dae</uri>
            </mesh>
          </geometry>
        </visual>
        <self_collide>0</self_collide>
        <enable_wind>0</enable_wind>
        <kinematic>0</kinematic>
      </link>
      <joint name='mano' type='revolute'>
        <child>link4</child>
        <parent>link3</parent>
        <axis>
          <xyz>-1e-06 -1 0</xyz>
          <limit>
            <lower>-1.94</lower>
            <upper>1.9</upper>
            <effort>1000</effort>
            <velocity>0.5</velocity>
          </limit>
          <dynamics>
            <spring_reference>0</spring_reference>
            <spring_stiffness>0</spring_stiffness>
          </dynamics>
          <use_parent_model_frame>1</use_parent_model_frame>
        </axis>
      </joint>
      <link name='link5'>
        <pose frame=''>0 -0 0.339333 -1.57079 -1.57079 3.14159</pose>
        <inertial>
          <pose frame=''>0.0716 0 0.028333 -1.5708 3e-06 -1.5708</pose>
          <mass>0.018</mass>
          <inertia>
            <ixx>0.10551</ixx>
            <ixy>-0.04561</ixy>
            <ixz>0.03274</ixz>
            <iyy>0.08842</iyy>
            <iyz>0.0425</iyz>
            <izz>0.12897</izz>
          </inertia>
        </inertial>
        <collision name='link5_collision'>
          <pose frame=''>0.0716 0 0.028333 -1.5708 3e-06 -1.5708</pose>
          <geometry>
            <mesh>
              <scale>1 1 1</scale>
              <uri>/home/gustavo/catkin_ws/src/Robotica-ProyectoIntermedio/Intermedio/meshes/PincheFinger.dae</uri>
            </mesh>
          </geometry>
          <max_contacts>10</max_contacts>
          <surface>
            <contact>
              <ode/>
            </contact>
            <bounce/>
            <friction>
              <torsional>
                <ode/>
              </torsional>
              <ode/>
            </friction>
          </surface>
        </collision>
        <visual name='link5_visual'>
          <pose frame=''>0.0716 0 0.028333 -1.5708 3e-06 -1.5708</pose>
          <geometry>
            <mesh>
              <scale>1 1 1</scale>
              <uri>/home/gustavo/catkin_ws/src/Robotica-ProyectoIntermedio/Intermedio/meshes/PincheFinger.dae</uri>
            </mesh>
          </geometry>
        </visual>
        <self_collide>0</self_collide>
        <enable_wind>0</enable_wind>
        <kinematic>0</kinematic>
      </link>
      <joint name='gripper0' type='prismatic'>
        <child>link5</child>
        <parent>link4</parent>
        <axis>
          <xyz>1e-06 1 -0</xyz>
          <limit>
            <lower>0</lower>
            <upper>0.015</upper>
            <effort>100</effort>
            <velocity>0.5</velocity>
          </limit>
          <dynamics>
            <spring_reference>0</spring_reference>
            <spring_stiffness>0</spring_stiffness>
          </dynamics>
          <use_parent_model_frame>1</use_parent_model_frame>
        </axis>
      </joint>
      <link name='link6'>
        <pose frame=''>0 -0 0.339333 -1.57079 -1.57079 3.14159</pose>
        <inertial>
          <pose frame=''>0.0716 0 -0.028333 1.57079 -0 1.57079</pose>
          <mass>0.057</mass>
          <inertia>
            <ixx>0.10551</ixx>
            <ixy>-0.04561</ixy>
            <ixz>0.03274</ixz>
            <iyy>0.08842</iyy>
            <iyz>0.0425</iyz>
            <izz>0.12897</izz>
          </inertia>
        </inertial>
        <collision name='link6_collision'>
          <pose frame=''>0.0716 0 -0.028333 1.57079 -0 1.57079</pose>
          <geometry>
            <mesh>
              <scale>1 1 1</scale>
              <uri>/home/gustavo/catkin_ws/src/Robotica-ProyectoIntermedio/Intermedio/meshes/PincheFinger.dae</uri>
            </mesh>
          </geometry>
          <max_contacts>10</max_contacts>
          <surface>
            <contact>
              <ode/>
            </contact>
            <bounce/>
            <friction>
              <torsional>
                <ode/>
              </torsional>
              <ode/>
            </friction>
          </surface>
        </collision>
        <visual name='link6_visual'>
          <pose frame=''>0.0716 0 -0.028333 1.57079 -0 1.57079</pose>
          <geometry>
            <mesh>
              <scale>1 1 1</scale>
              <uri>/home/gustavo/catkin_ws/src/Robotica-ProyectoIntermedio/Intermedio/meshes/PincheFinger.dae</uri>
            </mesh>
          </geometry>
        </visual>
        <self_collide>0</self_collide>
        <enable_wind>0</enable_wind>
        <kinematic>0</kinematic>
      </link>
      <joint name='gripper1' type='prismatic'>
        <child>link6</child>
        <parent>link4</parent>
        <axis>
          <xyz>-1e-06 -1 0</xyz>
          <limit>
            <lower>0</lower>
            <upper>0.015</upper>
            <effort>100</effort>
            <velocity>0.5</velocity>
          </limit>
          <dynamics>
            <spring_reference>0</spring_reference>
            <spring_stiffness>0</spring_stiffness>
          </dynamics>
          <use_parent_model_frame>1</use_parent_model_frame>
        </axis>
      </joint>
      <static>0</static>
      <plugin name='gazebo_ros_control' filename='libgazebo_ros_control.so'>
        <robotSimType>gazebo_ros_control/DefaultRobotHWSim</robotSimType>
        <legacyModeNS>1</legacyModeNS>
        <robotNamespace>/robot_1/</robotNamespace>
      </plugin>
      <pose frame=''>0 0.25 0 0 -0 0</pose>
    </model>
    <model name='camera'>
      <link name='camera_link'>
        <pose frame=''>0 0 1 3.14159 1.57079 3.14159</pose>
        <inertial>
          <pose frame=''>0 0 0 0 -0 0</pose>
          <mass>1e-05</mass>
          <inertia>
            <ixx>1e-06</ixx>
            <ixy>0</ixy>
            <ixz>0</ixz>
            <iyy>1e-06</iyy>
            <iyz>0</iyz>
            <izz>1e-06</izz>
          </inertia>
        </inertial>
        <collision name='camera_link_collision'>
          <pose frame=''>0 0 0 0 -0 0</pose>
          <geometry>
            <box>
              <size>0.05 0.05 0.05</size>
            </box>
          </geometry>
          <surface>
            <contact>
              <ode/>
            </contact>
            <friction>
              <ode/>
              <torsional>
                <ode/>
              </torsional>
            </friction>
            <bounce/>
          </surface>
          <max_contacts>10</max_contacts>
        </collision>
        <visual name='camera_link_visual'>
          <pose frame=''>0 0 0 0 -0 0</pose>
          <geometry>
            <box>
              <size>0.05 0.05 0.05</size>
            </box>
          </geometry>
          <material>
            <script>
              <uri>__default__</uri>
              <name>__default__</name>
            </script>
          </material>
        </visual>
        <gravity>1</gravity>
        <velocity_decay/>
        <sensor name='camera1' type='camera'>
          <update_rate>20</update_rate>
          <camera name='head'>
            <horizontal_fov>1.39626</horizontal_fov>
            <image>
              <width>400</width>
              <height>400</height>
              <format>R8G8B8</format>
            </image>
            <clip>
              <near>0.02</near>
              <far>300</far>
            </clip>
          </camera>
          <plugin name='camera_controller' filename='libgazebo_ros_camera.so'>
            <alwaysOn>1</alwaysOn>
            <updateRate>0.0</updateRate>
            <cameraName>camera1</cameraName>
            <imageTopicName>image_raw</imageTopicName>
            <cameraInfoTopicName>camera_info</cameraInfoTopicName>
            <frameName>camera_link_optical</frameName>
            <hackBaseline>0.0</hackBaseline>
            <distortionK1>0.0</distortionK1>
            <distortionK2>0.0</distortionK2>
            <distortionK3>0.0</distortionK3>
            <distortionT1>0.0</distortionT1>
            <distortionT2>0.0</distortionT2>
            <CxPrime>0</CxPrime>
            <Cx>0.0</Cx>
            <Cy>0.0</Cy>
            <focalLength>0.0</focalLength>
            <robotNamespace>/</robotNamespace>
          </plugin>
        </sensor>
        <self_collide>0</self_collide>
        <enable_wind>0</enable_wind>
        <kinematic>0</kinematic>
      </link>
      <joint name='fixed' type='fixed'>
        <child>camera_link</child>
        <parent>world</parent>
      </joint>
      <pose frame=''>0 0 0 0 -0 0</pose>
    </model>
    <model name='phantomXPincher2'>
      <link name='base_link'>
        <pose frame=''>0 0 0 0 -0 0</pose>
        <inertial>
          <pose frame=''>0 0 0 0 -0 3.14159</pose>
          <mass>0.561</mass>
          <inertia>
            <ixx>158.994</ixx>
            <ixy>-90.0553</ixy>
            <ixz>-15.0968</ixz>
            <iyy>66.0441</iyy>
            <iyz>-24.165</iyz>
            <izz>212.743</izz>
          </inertia>
        </inertial>
        <collision name='base_link_collision'>
          <pose frame=''>0 0 0 0 -0 3.14159</pose>
          <geometry>
            <mesh>
              <scale>1 1 1</scale>
              <uri>/home/gustavo/catkin_ws/src/Robotica-ProyectoIntermedio/Intermedio/meshes/PincherBase.dae</uri>
            </mesh>
          </geometry>
          <max_contacts>10</max_contacts>
          <surface>
            <contact>
              <ode/>
            </contact>
            <bounce/>
            <friction>
              <torsional>
                <ode/>
              </torsional>
              <ode/>
            </friction>
          </surface>
        </collision>
        <visual name='base_link_visual'>
          <pose frame=''>0 0 0 0 -0 3.14159</pose>
          <geometry>
            <mesh>
              <scale>1 1 1</scale>
              <uri>/home/gustavo/catkin_ws/src/Robotica-ProyectoIntermedio/Intermedio/meshes/PincherBase.dae</uri>
            </mesh>
          </geometry>
        </visual>
        <self_collide>0</self_collide>
        <enable_wind>0</enable_wind>
        <kinematic>0</kinematic>
      </link>
      <joint name='fixed' type='fixed'>
        <child>base_link</child>
        <parent>world</parent>
      </joint>
      <link name='link1'>
        <pose frame=''>0 0 0.053333 0 -0 0</pose>
        <inertial>
          <pose frame=''>0 0 0.03 0 -0 0</pose>
          <mass>0.069</mass>
          <inertia>
            <ixx>0.73346</ixx>
            <ixy>0</ixy>
            <ixz>0</ixz>
            <iyy>0.14452</iyy>
            <iyz>0</iyz>
            <izz>0.70391</izz>
          </inertia>
        </inertial>
        <collision name='link1_collision'>
          <pose frame=''>0 0 0.03 0 -0 0</pose>
          <geometry>
            <mesh>
              <scale>1 1 1</scale>
              <uri>/home/gustavo/catkin_ws/src/Robotica-ProyectoIntermedio/Intermedio/meshes/PincherLink1.dae</uri>
            </mesh>
          </geometry>
          <max_contacts>10</max_contacts>
          <surface>
            <contact>
              <ode/>
            </contact>
            <bounce/>
            <friction>
              <torsional>
                <ode/>
              </torsional>
              <ode/>
            </friction>
          </surface>
        </collision>
        <visual name='link1_visual'>
          <pose frame=''>0 0 0.03 0 -0 0</pose>
          <geometry>
            <mesh>
              <scale>1 1 1</scale>
              <uri>/home/gustavo/catkin_ws/src/Robotica-ProyectoIntermedio/Intermedio/meshes/PincherLink1.dae</uri>
            </mesh>
          </geometry>
        </visual>
        <self_collide>0</self_collide>
        <enable_wind>0</enable_wind>
        <kinematic>0</kinematic>
      </link>
      <joint name='cadera' type='revolute'>
        <child>link1</child>
        <parent>base_link</parent>
        <axis>
          <xyz>0 0 1</xyz>
          <limit>
            <lower>-2.61799</lower>
            <upper>2.618</upper>
            <effort>1000</effort>
            <velocity>0.5</velocity>
          </limit>
          <dynamics>
            <spring_reference>0</spring_reference>
            <spring_stiffness>0</spring_stiffness>
          </dynamics>
          <use_parent_model_frame>1</use_parent_model_frame>
        </axis>
      </joint>
      <link name='link2'>
        <pose frame=''>0 0 0.125333 -1.57079 -1.57079 3.14159</pose>
        <inertial>
          <pose frame=''>0 0 0 1.57079 -0 1.57079</pose>
          <mass>0.113</mass>
          <inertia>
            <ixx>7.19462</ixx>
            <ixy>-0.00352</ixy>
            <ixz>0</ixz>
            <iyy>0.27381</iyy>
            <iyz>0</iyz>
            <izz>7.10335</izz>
          </inertia>
        </inertial>
        <collision name='link2_collision'>
          <pose frame=''>0 0 0 1.57079 -0 1.57079</pose>
          <geometry>
            <mesh>
              <scale>1 1 1</scale>
              <uri>/home/gustavo/catkin_ws/src/Robotica-ProyectoIntermedio/Intermedio/meshes/PincherLink2.dae</uri>
            </mesh>
          </geometry>
          <max_contacts>10</max_contacts>
          <surface>
            <contact>
              <ode/>
            </contact>
            <bounce/>
            <friction>
              <torsional>
                <ode/>
              </torsional>
              <ode/>
            </friction>
          </surface>
        </collision>
        <visual name='link2_visual'>
          <pose frame=''>0 0 0 1.57079 -0 1.57079</pose>
          <geometry>
            <mesh>
              <scale>1 1 1</scale>
              <uri>/home/gustavo/catkin_ws/src/Robotica-ProyectoIntermedio/Intermedio/meshes/PincherLink2.dae</uri>
            </mesh>
          </geometry>
        </visual>
        <self_collide>0</self_collide>
        <enable_wind>0</enable_wind>
        <kinematic>0</kinematic>
      </link>
      <joint name='hombro' type='revolute'>
        <child>link2</child>
        <parent>link1</parent>
        <axis>
          <xyz>-1e-06 -1 0</xyz>
          <limit>
            <lower>-2</lower>
            <upper>2.61799</upper>
            <effort>1000</effort>
            <velocity>0.5</velocity>
          </limit>
          <dynamics>
            <spring_reference>0</spring_reference>
            <spring_stiffness>0</spring_stiffness>
          </dynamics>
          <use_parent_model_frame>1</use_parent_model_frame>
        </axis>
      </joint>
      <link name='link3'>
        <pose frame=''>0 -0 0.232333 -1.57079 -1.57079 3.14159</pose>
        <inertial>
          <pose frame=''>0 0 0 1.57079 -0 1.57079</pose>
          <mass>0.113</mass>
          <inertia>
            <ixx>7.19462</ixx>
            <ixy>-0.00352</ixy>
            <ixz>0</ixz>
            <iyy>0.27381</iyy>
            <iyz>0</iyz>
            <izz>7.10335</izz>
          </inertia>
        </inertial>
        <collision name='link3_collision'>
          <pose frame=''>0 0 0 1.57079 -0 1.57079</pose>
          <geometry>
            <mesh>
              <scale>1 1 1</scale>
              <uri>/home/gustavo/catkin_ws/src/Robotica-ProyectoIntermedio/Intermedio/meshes/PincherLink3.dae</uri>
            </mesh>
          </geometry>
          <max_contacts>10</max_contacts>
          <surface>
            <contact>
              <ode/>
            </contact>
            <bounce/>
            <friction>
              <torsional>
                <ode/>
              </torsional>
              <ode/>
            </friction>
          </surface>
        </collision>
        <visual name='link3_visual'>
          <pose frame=''>0 0 0 1.57079 -0 1.57079</pose>
          <geometry>
            <mesh>
              <scale>1 1 1</scale>
              <uri>/home/gustavo/catkin_ws/src/Robotica-ProyectoIntermedio/Intermedio/meshes/PincherLink3.dae</uri>
            </mesh>
          </geometry>
        </visual>
        <self_collide>0</self_collide>
        <enable_wind>0</enable_wind>
        <kinematic>0</kinematic>
      </link>
      <joint name='codo' type='revolute'>
        <child>link3</child>
        <parent>link2</parent>
        <axis>
          <xyz>-1e-06 -1 0</xyz>
          <limit>
            <lower>-2.52</lower>
            <upper>2.52</upper>
            <effort>1000</effort>
            <velocity>0.5</velocity>
          </limit>
          <dynamics>
            <spring_reference>0</spring_reference>
            <spring_stiffness>0</spring_stiffness>
          </dynamics>
          <use_parent_model_frame>1</use_parent_model_frame>
        </axis>
      </joint>
      <link name='link4'>
        <pose frame=''>0 -0 0.339333 -1.57079 -1.57079 3.14159</pose>
        <inertial>
          <pose frame=''>0 0 0 1.57079 -0 1.57079</pose>
          <mass>0.057</mass>
          <inertia>
            <ixx>0.25116</ixx>
            <ixy>0.14167</ixy>
            <ixz>0</ixz>
            <iyy>0.43376</iyy>
            <iyz>0</iyz>
            <izz>0.57362</izz>
          </inertia>
        </inertial>
        <collision name='link4_collision'>
          <pose frame=''>0 0 0 1.57079 -0 1.57079</pose>
          <geometry>
            <mesh>
              <scale>1 1 1</scale>
              <uri>/home/gustavo/catkin_ws/src/Robotica-ProyectoIntermedio/Intermedio/meshes/PincherTool.dae</uri>
            </mesh>
          </geometry>
          <max_contacts>10</max_contacts>
          <surface>
            <contact>
              <ode/>
            </contact>
            <bounce/>
            <friction>
              <torsional>
                <ode/>
              </torsional>
              <ode/>
            </friction>
          </surface>
        </collision>
        <visual name='link4_visual'>
          <pose frame=''>0 0 0 1.57079 -0 1.57079</pose>
          <geometry>
            <mesh>
              <scale>1 1 1</scale>
              <uri>/home/gustavo/catkin_ws/src/Robotica-ProyectoIntermedio/Intermedio/meshes/PincherTool.dae</uri>
            </mesh>
          </geometry>
        </visual>
        <self_collide>0</self_collide>
        <enable_wind>0</enable_wind>
        <kinematic>0</kinematic>
      </link>
      <joint name='mano' type='revolute'>
        <child>link4</child>
        <parent>link3</parent>
        <axis>
          <xyz>-1e-06 -1 0</xyz>
          <limit>
            <lower>-1.94</lower>
            <upper>1.9</upper>
            <effort>1000</effort>
            <velocity>0.5</velocity>
          </limit>
          <dynamics>
            <spring_reference>0</spring_reference>
            <spring_stiffness>0</spring_stiffness>
          </dynamics>
          <use_parent_model_frame>1</use_parent_model_frame>
        </axis>
      </joint>
      <link name='link5'>
        <pose frame=''>0 -0 0.339333 -1.57079 -1.57079 3.14159</pose>
        <inertial>
          <pose frame=''>0.0716 0 0.028333 -1.5708 3e-06 -1.5708</pose>
          <mass>0.018</mass>
          <inertia>
            <ixx>0.10551</ixx>
            <ixy>-0.04561</ixy>
            <ixz>0.03274</ixz>
            <iyy>0.08842</iyy>
            <iyz>0.0425</iyz>
            <izz>0.12897</izz>
          </inertia>
        </inertial>
        <collision name='link5_collision'>
          <pose frame=''>0.0716 0 0.028333 -1.5708 3e-06 -1.5708</pose>
          <geometry>
            <mesh>
              <scale>1 1 1</scale>
              <uri>/home/gustavo/catkin_ws/src/Robotica-ProyectoIntermedio/Intermedio/meshes/PincheFinger.dae</uri>
            </mesh>
          </geometry>
          <max_contacts>10</max_contacts>
          <surface>
            <contact>
              <ode/>
            </contact>
            <bounce/>
            <friction>
              <torsional>
                <ode/>
              </torsional>
              <ode/>
            </friction>
          </surface>
        </collision>
        <visual name='link5_visual'>
          <pose frame=''>0.0716 0 0.028333 -1.5708 3e-06 -1.5708</pose>
          <geometry>
            <mesh>
              <scale>1 1 1</scale>
              <uri>/home/gustavo/catkin_ws/src/Robotica-ProyectoIntermedio/Intermedio/meshes/PincheFinger.dae</uri>
            </mesh>
          </geometry>
        </visual>
        <self_collide>0</self_collide>
        <enable_wind>0</enable_wind>
        <kinematic>0</kinematic>
      </link>
      <joint name='gripper0' type='prismatic'>
        <child>link5</child>
        <parent>link4</parent>
        <axis>
          <xyz>1e-06 1 -0</xyz>
          <limit>
            <lower>0</lower>
            <upper>0.015</upper>
            <effort>100</effort>
            <velocity>0.5</velocity>
          </limit>
          <dynamics>
            <spring_reference>0</spring_reference>
            <spring_stiffness>0</spring_stiffness>
          </dynamics>
          <use_parent_model_frame>1</use_parent_model_frame>
        </axis>
      </joint>
      <link name='link6'>
        <pose frame=''>0 -0 0.339333 -1.57079 -1.57079 3.14159</pose>
        <inertial>
          <pose frame=''>0.0716 0 -0.028333 1.57079 -0 1.57079</pose>
          <mass>0.057</mass>
          <inertia>
            <ixx>0.10551</ixx>
            <ixy>-0.04561</ixy>
            <ixz>0.03274</ixz>
            <iyy>0.08842</iyy>
            <iyz>0.0425</iyz>
            <izz>0.12897</izz>
          </inertia>
        </inertial>
        <collision name='link6_collision'>
          <pose frame=''>0.0716 0 -0.028333 1.57079 -0 1.57079</pose>
          <geometry>
            <mesh>
              <scale>1 1 1</scale>
              <uri>/home/gustavo/catkin_ws/src/Robotica-ProyectoIntermedio/Intermedio/meshes/PincheFinger.dae</uri>
            </mesh>
          </geometry>
          <max_contacts>10</max_contacts>
          <surface>
            <contact>
              <ode/>
            </contact>
            <bounce/>
            <friction>
              <torsional>
                <ode/>
              </torsional>
              <ode/>
            </friction>
          </surface>
        </collision>
        <visual name='link6_visual'>
          <pose frame=''>0.0716 0 -0.028333 1.57079 -0 1.57079</pose>
          <geometry>
            <mesh>
              <scale>1 1 1</scale>
              <uri>/home/gustavo/catkin_ws/src/Robotica-ProyectoIntermedio/Intermedio/meshes/PincheFinger.dae</uri>
            </mesh>
          </geometry>
        </visual>
        <self_collide>0</self_collide>
        <enable_wind>0</enable_wind>
        <kinematic>0</kinematic>
      </link>
      <joint name='gripper1' type='prismatic'>
        <child>link6</child>
        <parent>link4</parent>
        <axis>
          <xyz>-1e-06 -1 0</xyz>
          <limit>
            <lower>0</lower>
            <upper>0.015</upper>
            <effort>100</effort>
            <velocity>0.5</velocity>
          </limit>
          <dynamics>
            <spring_reference>0</spring_reference>
            <spring_stiffness>0</spring_stiffness>
          </dynamics>
          <use_parent_model_frame>1</use_parent_model_frame>
        </axis>
      </joint>
      <static>0</static>
      <plugin name='gazebo_ros_control' filename='libgazebo_ros_control.so'>
        <robotSimType>gazebo_ros_control/DefaultRobotHWSim</robotSimType>
        <legacyModeNS>1</legacyModeNS>
        <robotNamespace>/robot_2/</robotNamespace>
      </plugin>
      <pose frame=''>0 -0.25 0 0 -0 0</pose>
    </model>
    <model name='unit_box_2'>
      <pose frame=''>0.885755 0.168429 0.5 0 -0 0</pose>
      <link name='link'>
        <inertial>
          <mass>1</mass>
          <inertia>
            <ixx>0.166667</ixx>
            <ixy>0</ixy>
            <ixz>0</ixz>
            <iyy>0.166667</iyy>
            <iyz>0</iyz>
            <izz>0.166667</izz>
          </inertia>
        </inertial>
        <collision name='collision'>
          <geometry>
            <box>
              <size>1 0.999996 0.999999</size>
            </box>
          </geometry>
          <max_contacts>10</max_contacts>
          <surface>
            <contact>
              <ode/>
            </contact>
            <bounce/>
            <friction>
              <torsional>
                <ode/>
              </torsional>
              <ode/>
            </friction>
          </surface>
        </collision>
        <visual name='visual'>
          <geometry>
            <box>
              <size>1 0.999996 0.999999</size>
            </box>
          </geometry>
          <material>
            <script>
              <name>Gazebo/Grey</name>
              <uri>file://media/materials/scripts/gazebo.material</uri>
            </script>
          </material>
        </visual>
        <self_collide>0</self_collide>
        <enable_wind>0</enable_wind>
        <kinematic>0</kinematic>
      </link>
    </model>
  </world>
</sdf>
